<?xml version="1.0"?>
<robot xmlns:xacro="http://www.ros.org/wiki/xacro" name="aluminum">
    <xacro:include filename="inertials.xacro"/>

    <material name="white">
        <color rgba="1 1 1 1"/> 
    </material>

    <material name="black">
        <color rgba="0 0 0 1"/> 
    </material>

    <!-- base footprint -->
    <link name="base_footprint">
        
    </link>

    <!-- base link -->
    <joint name="base_link_joint" type="fixed">
        <parent link="base_footprint"/>
        <child link="base_link"/>
        <origin xyz="0.0 0.0 0.005"/>
    </joint>

    <link name="base_link">
        <origin xyz="0.0 0.0 0.0"/>
    </link>

    <!-- chassis -->
    <joint name="chassis_joint" type="fixed">
        <parent link="base_link"/>
        <child link="chassis"/>
        <origin xyz="0.0 0.0 0.04"/>
    </joint>

    <link name="chassis">
        <visual>
            <geometry>
                <cylinder radius="0.175" length="0.08"/>
            </geometry>
            <material name="white"/>
        </visual>

        <collision>
            <geometry>
                <cylinder radius="0.175" length="0.08"/>
            </geometry>
        </collision>

    <xacro:inertial_cylinder mass = "4.2" length="0.08" radius="0.175">
        <origin xyz="0.0 0.0 0.0" rpy="0.0 0.0 0.0"/>
    </xacro:inertial_cylinder>         
    </link>
    
    <!-- left wheel -->
    <joint name="left_wheel_joint" type="continuous">
        <parent link="chassis"/>
        <child link="left_wheel"/>
        <origin xyz="0.0 0.13 -0.005" rpy="-${pi/2} 0 0.0"/>
        <axis xyz="0.0 0.0 1"/>
    </joint>

    <link name="left_wheel">
        <visual>
            <geometry>
                <cylinder radius="0.04" length="0.02"/>
            </geometry>
            <material name="black"/>
        </visual>

        <collision>
            <geometry>
                <cylinder radius="0.04" length="0.02"/>
            </geometry>
        </collision>

    <xacro:inertial_cylinder mass = "0.1" length="0.02" radius="0.04">
        <origin xyz="0.0 0.0 0.0" rpy="0.0 0.0 0.0"/>
    </xacro:inertial_cylinder>  
    </link>

    <!-- right wheel -->
    <joint name="right_wheel_joint" type="continuous">
        <parent link="chassis"/>
        <child link="right_wheel"/>
        <origin xyz="0.0 -0.13 -0.005" rpy="${pi/2} 0 0.0"/>
        <axis xyz="0.0 0.0 -1"/>
    </joint>

    <link name="right_wheel">
        <visual>
            <geometry>
                <cylinder radius="0.04" length="0.02"/>
            </geometry>
            <material name="black"/>
        </visual>

        <collision>
            <geometry>
                <cylinder radius="0.04" length="0.02"/>
            </geometry>
        </collision>

    <xacro:inertial_cylinder mass = "0.1" length="0.02" radius="0.04">
        <origin xyz="0.0 0.0 0.0" rpy="0.0 0.0 0.0"/>
    </xacro:inertial_cylinder> 
    </link>    

    <!-- front caster -->
    <joint name="front_caster_joint" type="fixed">
        <parent link="chassis"/>
        <child link="front_caster"/>
        <origin xyz="0.145 0.0 -0.035"/>
    </joint>

    <link name="front_caster">
        <visual>
            <geometry>
                <sphere radius="0.01"/>
            </geometry>
        </visual>

        <collision>
            <geometry>
                <sphere radius="0.01"/>
            </geometry>
        </collision>

        <xacro:inertial_sphere mass = "0.06" radius="0.01">
            <origin xyz="0.0 0.0 0.0" rpy="0.0 0.0 0.0"/>
        </xacro:inertial_sphere>         
    </link>

    <!-- rear caster -->
    <joint name="rear_caster_joint" type="fixed">
        <parent link="chassis"/>
        <child link="rear_caster"/>
        <origin xyz="-0.145 0.0 -0.035"/>
    </joint>

    <link name="rear_caster">
        <visual>
            <geometry>
                <sphere radius="0.01"/>
            </geometry>
        </visual>

        <collision>
            <geometry>
                <sphere radius="0.01"/>
            </geometry>
        </collision>

        <xacro:inertial_sphere mass = "0.06" radius="0.01">
            <origin xyz="0.0 0.0 0.0" rpy="0.0 0.0 0.0"/>
        </xacro:inertial_sphere>  
    </link>
</robot>